Workbook

Sheet Portage Bill
Q1: Cr-17 | AF1: Cr-17
F2: From : | G2: 41365 | J2: To : | K2: 41394
B3: Vessel: | E3: Currency: USD | Q3: 1 of 3 | AF3: 2 of 3
B4: OWNERS: Sea Traffic Shipping Co. | F4: M O N T H L Y | J4: P O R T A G E B I L L
F5: BASIC Pay | K5: ALLOWANCE | L5: =L56 -> Travelling | M5: LEAVE | O5: =J57 -> BONUS | Q5: TOTAL EARNINGS | R5: D E D U C T I O N S | AA5: BALANCE | AB5: PREVIOUS BALANCE | AC5: ****Leave pay for off-signers | AD5: FINAL BALLANCE | AE5: SIGNATURE
A6: No. | B6: NAME | D6: RANK | H6: OVERTIME | J6: FIDELITY | P6: Bonus & Extras
F7: DAYS | G7: AMOUNT | H7: HOUR | I7: AMOUNT | J7: BONUS | M7: DAYS | N7: AMOUNT | R7: ***Leave pay | S7: Allotmеnt | T7: SING. PAYM. | U7: CASH ADV.1 | V7: CASH ADV.2 | W7: Slopchest | X7: Telecon | Y7: Other | Z7: TOTAL DEDUCTIONS
A8: 1 | D8: Master | F8: 0 | G8: =(F59/30)*F8 -> 0 | I8: =(H59/30)*F8 -> 0 | J8: =(G59/30)*F8 -> 0 | K8: 0 | L8: =M59 -> 0 | N8: =(I59/30)*F8 -> 0 | O8: =(J59/30)*F8 -> 0 | P8: 0 | Q8: =G8+I8+J8+K8+L8+N8+O8+P8 -> 0 | R8: =N8 -> 0 | Z8: =SUM(R8:Y8) -> 0 | AA8: =Q8-Z8 -> 0 | AB8: 0 | AC8: ='deduct list'!U10 -> 0 | AD8: =SUM(AA8:AB8)+AC8 -> 0
A9: =A8+1 -> 2 | D9: Chief officer | F9: 0 | G9: =(F60/30)*F9 -> 0 | I9: =(H60/30)*F9 -> 0 | J9: =(G60/30)*F9 -> 0 | K9: =(K60/30)*F9 -> 0 | L9: =M60 -> 0 | N9: =(I60/30)*F9 -> 0 | O9: =(J60/30)*F9 -> 0 | P9: 0 | Q9: =G9+I9+J9+K9+L9+N9+O9+P9 -> 0 | R9: =N9 -> 0 | Z9: =SUM(R9:Y9) -> 0 | AA9: =Q9-Z9 -> 0 | AB9: 0 | AC9: ='deduct list'!U11 -> 0 | AD9: =SUM(AA9:AB9)+AC9 -> 0
A10: =A9+1 -> 3 | D10: 2nd Officer | F10: 0 | G10: =(F61/30)*F10 -> 0 | I10: =(H61/30)*F10 -> 0 | J10: =(G61/30)*F10 -> 0 | K10: =(K61/30)*F10 -> 0 | L10: =M61 -> 0 | N10: =(I61/30)*F10 -> 0 | O10: =(J61/30)*F10 -> 0 | P10: 0 | Q10: =G10+I10+J10+K10+L10+N10+O10+P10 -> 0 | R10: =N10 -> 0 | Z10: =SUM(R10:Y10) -> 0 | AA10: =Q10-Z10 -> 0 | AB10: 0 | AC10: ='deduct list'!U12 -> 0 | AD10: =SUM(AA10:AB10)+AC10 -> 0
A11: =A10+1 -> 4 | D11: 3d Officer | F11: 0 | G11: =(F62/30)*F11 -> 0 | I11: =(H62/30)*F11 -> 0 | J11: =(G62/30)*F11 -> 0 | K11: =(K62/30)*F11 -> 0 | L11: =M62 -> 0 | N11: =(I62/30)*F11 -> 0 | O11: =(J62/30)*F11 -> 0 | P11: 0 | Q11: =G11+I11+J11+K11+L11+N11+O11+P11 -> 0 | R11: =N11 -> 0 | Z11: =SUM(R11:Y11) -> 0 | AA11: =Q11-Z11 -> 0 | AB11: 0 | AC11: ='deduct list'!U13 -> 0 | AD11: =SUM(AA11:AB11)+AC11 -> 0
A12: =A11+1 -> 5 | D12: Chief Engineer | F12: 0 | G12: =(F63/30)*F12 -> 0 | I12: =(H63/30)*F12 -> 0 | J12: =(G63/30)*F12 -> 0 | K12: =(K63/30)*F12 -> 0 | L12: =M63 -> 0 | N12: =(I63/30)*F12 -> 0 | O12: =(J63/30)*F12 -> 0 | P12: =N63/E63*F12 -> 0 | Q12: =G12+I12+J12+K12+L12+N12+O12+P12 -> 0 | R12: =N12 -> 0 | Z12: =SUM(R12:Y12) -> 0 | AA12: =Q12-Z12 -> 0 | AB12: 0 | AC12: ='deduct list'!U14 -> 0 | AD12: =SUM(AA12:AB12)+AC12 -> 0
A13: =A12+1 -> 6 | D13: 2nd Engineer | F13: 0 | G13: =(F64/30)*F13 -> 0 | I13: =(H64/30)*F13 -> 0 | J13: =(G64/30)*F13 -> 0 | K13: =(K64/30)*F13 -> 0 | L13: =M64 -> 0 | N13: =(I64/30)*F13 -> 0 | O13: =(J64/30)*F13 -> 0 | P13: =N64/E64*F13 -> 0 | Q13: =G13+I13+J13+K13+L13+N13+O13+P13 -> 0 | R13: =N13 -> 0 | Z13: =SUM(R13:Y13) -> 0 | AA13: =Q13-Z13 -> 0 | AB13: 0 | AC13: ='deduct list'!U15 -> 0 | AD13: =SUM(AA13:AB13)+AC13 -> 0
A14: =A13+1 -> 7 | D14: 3d Engineer | F14: 0 | G14: =(F65/30)*F14 -> 0 | I14: =(H65/30)*F14 -> 0 | J14: =(G65/30)*F14 -> 0 | K14: =(K65/30)*F14 -> 0 | L14: =M65 -> 0 | N14: =(I65/30)*F14 -> 0 | O14: =(J65/30)*F14 -> 0 | P14: =N65/E65*F14 -> 0 | Q14: =G14+I14+J14+K14+L14+N14+O14+P14 -> 0 | R14: =N14 -> 0 | Z14: =SUM(R14:Y14) -> 0 | AA14: =Q14-Z14 -> 0 | AB14: 0 | AC14: ='deduct list'!U16 -> 0 | AD14: =SUM(AA14:AB14)+AC14 -> 0
A15: =A14+1 -> 8 | D15: 4th Engineer | F15: 0 | G15: =(F66/30)*F15 -> 0 | I15: =(H66/30)*F15 -> 0 | J15: =(G66/30)*F15 -> 0 | K15: =(K66/30)*F15 -> 0 | L15: =M66 -> 0 | N15: =(I66/30)*F15 -> 0 | O15: =(J66/30)*F15 -> 0 | P15: =N66/E66*F15 -> 0 | Q15: =G15+I15+J15+K15+L15+N15+O15+P15 -> 0 | R15: =N15 -> 0 | Z15: =SUM(R15:Y15) -> 0 | AA15: =Q15-Z15 -> 0 | AB15: 0 | AC15: ='deduct list'!U17 -> 0 | AD15: =SUM(AA15:AB15)+AC15 -> 0
A16: =A15+1 -> 9 | D16: El.ENG | F16: 0 | G16: =(F67/30)*F16 -> 0 | I16: =(H67/30)*F16 -> 0 | J16: =(G67/30)*F16 -> 0 | K16: =(K67/30)*F16 -> 0 | L16: =M67 -> 0 | N16: =(I67/30)*F16 -> 0 | O16: =(J67/30)*F16 -> 0 | P16: =N67/E67*F16 -> 0 | Q16: =G16+I16+J16+K16+L16+N16+O16+P16 -> 0 | R16: =N16 -> 0 | Z16: =SUM(R16:Y16) -> 0 | AA16: =Q16-Z16 -> 0 | AB16: 0 | AC16: ='deduct list'!U18 -> 0 | AD16: =SUM(AA16:AB16)+AC16 -> 0
A17: =A16+1 -> 10 | D17: Bosun | F17: 0 | G17: =(F68/30)*F17 -> 0 | I17: =(H68/30)*F17 -> 0 | J17: =(G68/30)*F17 -> 0 | K17: =(K68/30)*F17 -> 0 | L17: =M68 -> 0 | N17: =(I68/30)*F17 -> 0 | O17: =(J68/30)*F17 -> 0 | P17: 0 | Q17: =G17+I17+J17+K17+L17+N17+O17+P17 -> 0 | R17: =N17 -> 0 | Z17: =SUM(R17:Y17) -> 0 | AA17: =Q17-Z17 -> 0 | AB17: 0 | AC17: ='deduct list'!U19 -> 0 | AD17: =SUM(AA17:AB17)+AC17 -> 0
A18: =A17+1 -> 11 | D18: ABS | F18: 0 | G18: =(F69/30)*F18 -> 0 | I18: =(H69/30)*F18 -> 0 | J18: =(G69/30)*F18 -> 0 | K18: =(K69/30)*F18 -> 0 | L18: =M69 -> 0 | N18: =(I69/30)*F18 -> 0 | O18: =(J69/30)*F18 -> 0 | P18: 0 | Q18: =G18+I18+J18+K18+L18+N18+O18+P18 -> 0 | R18: =N18 -> 0 | Z18: =SUM(R18:Y18) -> 0 | AA18: =Q18-Z18 -> 0 | AB18: 0 | AC18: ='deduct list'!U20 -> 0 | AD18: =SUM(AA18:AB18)+AC18 -> 0
A19: =A18+1 -> 12 | D19: ABS | F19: 0 | G19: =(F70/30)*F19 -> 0 | I19: =(H70/30)*F19 -> 0 | J19: =(G70/30)*F19 -> 0 | K19: =(K70/30)*F19 -> 0 | L19: =M70 -> 0 | N19: =(I70/30)*F19 -> 0 | O19: =(J70/30)*F19 -> 0 | P19: 0 | Q19: =G19+I19+J19+K19+L19+N19+O19+P19 -> 0 | R19: =N19 -> 0 | Z19: =SUM(R19:Y19) -> 0 | AA19: =Q19-Z19 -> 0 | AB19: 0 | AC19: ='deduct list'!U21 -> 0 | AD19: =SUM(AA19:AB19)+AC19 -> 0
A20: =A19+1 -> 13 | D20: ABS | F20: 0 | G20: =(F71/30)*F20 -> 0 | I20: =(H71/30)*F20 -> 0 | J20: =(G71/30)*F20 -> 0 | K20: =(K71/30)*F20 -> 0 | L20: =M71 -> 0 | N20: =(I71/30)*F20 -> 0 | O20: =(J71/30)*F20 -> 0 | P20: 0 | Q20: =G20+I20+J20+K20+L20+N20+O20+P20 -> 0 | R20: =N20 -> 0 | Z20: =SUM(R20:Y20) -> 0 | AA20: =Q20-Z20 -> 0 | AB20: 0 | AC20: ='deduct list'!U24 -> 0 | AD20: =SUM(AA20:AB20)+AC20 -> 0
A21: =A20+1 -> 14 | D21: OS | F21: 0 | G21: =(F72/30)*F21 -> 0 | I21: =(H72/30)*F21 -> 0 | J21: =(G72/30)*F21 -> 0 | K21: =(K72/30)*F21 -> 0 | L21: =M72 -> 0 | N21: =(I72/30)*F21 -> 0 | O21: =(J72/30)*F21 -> 0 | P21: 0 | Q21: =G21+I21+J21+K21+L21+N21+O21+P21 -> 0 | R21: =N21 -> 0 | Z21: =SUM(R21:Y21) -> 0 | AA21: =Q21-Z21 -> 0 | AB21: 0 | AC21: ='deduct list'!U25 -> 0 | AD21: =SUM(AA21:AB21)+AC21 -> 0
A22: =A21+1 -> 15 | D22: OS | F22: 0 | G22: =(F73/30)*F22 -> 0 | I22: =(H73/30)*F22 -> 0 | J22: =(G73/30)*F22 -> 0 | K22: =(K73/30)*F22 -> 0 | L22: =M73 -> 0 | N22: =(I73/30)*F22 -> 0 | O22: =(J73/30)*F22 -> 0 | P22: 0 | Q22: =G22+I22+J22+K22+L22+N22+O22+P22 -> 0 | R22: =N22 -> 0 | Z22: =SUM(R22:Y22) -> 0 | AA22: =Q22-Z22 -> 0 | AB22: 0 | AC22: ='deduct list'!U24 -> 0 | AD22: =SUM(AA22:AB22)+AC22 -> 0
A23: =A22+1 -> 16 | D23: Motorman | F23: 0 | G23: =(F74/30)*F23 -> 0 | I23: =(H74/30)*F23 -> 0 | J23: =(G74/30)*F23 -> 0 | K23: =(K74/30)*F23 -> 0 | L23: =M74 -> 0 | N23: =(I74/30)*F23 -> 0 | O23: =(J74/30)*F23 -> 0 | P23: =N74/E74*F23 -> 0 | Q23: =G23+I23+J23+K23+L23+N23+O23+P23 -> 0 | R23: =N23 -> 0 | Z23: =SUM(R23:Y23) -> 0 | AA23: =Q23-Z23 -> 0 | AB23: 0 | AC23: ='deduct list'!U25 -> 0 | AD23: =SUM(AA23:AB23)+AC23 -> 0
A24: 17 | D24: Motorman | F24: 0 | G24: =(F75/30)*F24 -> 0 | I24: =(H75/30)*F24 -> 0 | J24: =(G75/30)*F24 -> 0 | K24: =(K75/30)*F24 -> 0 | L24: =M75 -> 0 | N24: =(I75/30)*F24 -> 0 | O24: =(J75/30)*F24 -> 0 | P24: =N75/E75*F24 -> 0 | Q24: =G24+I24+J24+K24+L24+N24+O24+P24 -> 0 | R24: =N24 -> 0 | Z24: =SUM(R24:Y24) -> 0 | AA24: =Q24-Z24 -> 0 | AB24: 0 | AC24: ='deduct list'!U26 -> 0 | AD24: =SUM(AA24:AB24)+AC24 -> 0
A25: =A24+1 -> 18 | D25: Motorman | F25: 0 | G25: =(F76/30)*F25 -> 0 | I25: =(H76/30)*F25 -> 0 | J25: =(G76/30)*F25 -> 0 | K25: =(K76/30)*F25 -> 0 | L25: =M76 -> 0 | N25: =(I76/30)*F25 -> 0 | O25: =(J76/30)*F25 -> 0 | P25: =N76/E76*F25 -> 0 | Q25: =G25+I25+J25+K25+L25+N25+O25+P25 -> 0 | R25: =N25 -> 0 | Z25: =SUM(R25:Y25) -> 0 | AA25: =Q25-Z25 -> 0 | AB25: 0 | AC25: ='deduct list'!U27 -> 0 | AD25: =SUM(AA25:AB25)+AC25 -> 0
A26: =A25+1 -> 19 | D26: Wiper | F26: 0 | G26: =(F77/30)*F26 -> 0 | I26: =(H77/30)*F26 -> 0 | J26: =(G77/30)*F26 -> 0 | K26: =(K77/30)*F26 -> 0 | L26: =M77 -> 0 | N26: =(I77/30)*F26 -> 0 | O26: =(J77/30)*F26 -> 0 | P26: =N77/E77*F26 -> 0 | Q26: =G26+I26+J26+K26+L26+N26+O26+P26 -> 0 | R26: =N26 -> 0 | Z26: =SUM(R26:Y26) -> 0 | AA26: =Q26-Z26 -> 0 | AB26: 0 | AC26: ='deduct list'!U28 -> 0 | AD26: =SUM(AA26:AB26)+AC26 -> 0
A27: =A26+1 -> 20 | D27: CCK | F27: 0 | G27: =(F78/30)*F27 -> 0 | I27: =(H78/30)*F27 -> 0 | J27: =(G78/30)*F27 -> 0 | K27: =(K78/30)*F27 -> 0 | L27: =M78 -> 0 | N27: =(I78/30)*F27 -> 0 | O27: =(J78/30)*F27 -> 0 | P27: 0 | Q27: =G27+I27+J27+K27+L27+N27+O27+P27 -> 0 | R27: =N27 -> 0 | Z27: =SUM(R27:Y27) -> 0 | AA27: =Q27-Z27 -> 0 | AB27: 0 | AC27: ='deduct list'!U29 -> 0 | AD27: =SUM(AA27:AB27)+AC27 -> 0
A28: =A27+1 -> 21 | D28: MBOY | F28: 0 | G28: =(F79/30)*F28 -> 0 | I28: =(H79/30)*F28 -> 0 | J28: =(G79/30)*F28 -> 0 | K28: =(K79/30)*F28 -> 0 | L28: =M79 -> 0 | N28: =(I79/30)*F28 -> 0 | O28: =(J79/30)*F28 -> 0 | P28: =N79/E79*F28 -> 0 | Q28: =G28+I28+J28+K28+L28+N28+O28+P28 -> 0 | R28: =N28 -> 0 | Z28: =SUM(R28:Y28) -> 0 | AA28: =Q28-Z28 -> 0 | AB28: 0 | AC28: ='deduct list'!U30 -> 0 | AD28: =SUM(AA28:AB28)+AC28 -> 0
A29: =A28+1 -> 22 | D29: Deck Fitter | F29: 0 | G29: =(F80/30)*F29 -> 0 | I29: =(H80/30)*F29 -> 0 | J29: =(G80/30)*F29 -> 0 | K29: =(K80/30)*F29 -> 0 | L29: =M80 -> 0 | N29: =(I80/30)*F29 -> 0 | O29: =(J80/30)*F29 -> 0 | P29: 0 | Q29: =G29+I29+J29+K29+L29+N29+O29+P29 -> 0 | R29: =N29 -> 0 | Z29: =SUM(R29:Y29) -> 0 | AA29: =Q29-Z29 -> 0 | AB29: 0 | AC29: ='deduct list'!U31 -> 0 | AD29: =SUM(AA29:AB29)+AC29 -> 0
A30: =A29+1 -> 23 | D30: Engine Fitter | F30: 0 | G30: =(F81/30)*F30 -> 0 | I30: =(H81/30)*F30 -> 0 | J30: =(G81/30)*F30 -> 0 | K30: =(K81/30)*F30 -> 0 | L30: =M81 -> 0 | N30: =(I81/30)*F30 -> 0 | O30: =(J81/30)*F30 -> 0 | P30: =N81/E81*F30 -> 0 | Q30: =G30+I30+J30+K30+L30+N30+O30+P30 -> 0 | R30: =N30 -> 0 | Z30: =SUM(R30:Y30) -> 0 | AA30: =Q30-Z30 -> 0 | AB30: 0 | AC30: ='deduct list'!U32 -> 0 | AD30: =SUM(AA30:AB30)+AC30 -> 0
A31: =A30+1 -> 24 | D31: Electrician | F31: 0 | G31: =(F82/30)*F31 -> 0 | I31: =(H82/30)*F31 -> 0 | J31: =(G82/30)*F31 -> 0 | K31: =(K82/30)*F31 -> 0 | L31: =M82 -> 0 | N31: =(I82/30)*F31 -> 0 | O31: =(J82/30)*F31 -> 0 | P31: =N82/E82*F31 -> 0 | Q31: =G31+I31+J31+K31+L31+N31+O31+P31 -> 0 | R31: =N31 -> 0 | Z31: =SUM(R31:Y31) -> 0 | AA31: =Q31-Z31 -> 0 | AB31: 0 | AC31: ='deduct list'!U33 -> 0 | AD31: =SUM(AA31:AB31)+AC31 -> 0
B36: T O T A L | G36: =SUM(G8:G35) -> 0 | I36: =SUM(I8:I35) -> 0 | J36: =SUM(J8:J35) -> 0 | K36: =SUM(K8:K35) -> 0 | L36: =SUM(L8:L35) -> 0 | N36: =SUM(N8:N35) -> 0 | O36: =SUM(O8:O35) -> 0 | P36: =SUM(P8:P35) -> 0 | Q36: =SUM(Q8:Q35) -> 0 | R36: =SUM(R8:R35) -> 0 | S36: =SUM(S8:S35) -> 0 | T36: =SUM(T8:T35) -> 0 | U36: =SUM(U8:U35) -> 0 | ... AD36: =SUM(AD8:AD35) -> 0
D37: NOTE : | T37: ***Leave pay is payable at the end of the contract.
T38: **** Leave pay only for off-signers
G39: RANK | H39: NAME | L39: AMOUNT | N39: EXPLANATIONS | V39: RANK | W39: NAME | Z39: AMOUNT | AA39: EXPLANATIONS
A40: OVER - | B40: DECK
A41: TIME | F41: REMARKS | U41: REMARKS
A42: RATING | B42: ENGINE
B44: CATERING
D49: Master / /
...

Sheet deduct list
C1: ON BOARD DEDUCTION LIST
Q2: Revision Number | R2: Revision Number | S2: 01
Q3: Page Number | R3: Page Number | S3: 1 of 1
D6: ON BOARD DEDUCTION LIST
R7: Month: | S7: ='Portage Bill'!K2 -> 41394
C8: ='Portage Bill'!B3 -> Vessel: | D8: ='Portage Bill'!C3 -> 0
C9: NAME | D9: RANK | E9: ='Portage Bill'!Q5 -> TOTAL EARNINGS | F9: ='Portage Bill'!R7 -> ***Leave pay | G9: ='Portage Bill'!S7 -> Allotmеnt | H9: ='Portage Bill'!T7 -> SING. PAYM. | I9: ='Portage Bill'!U7 -> CASH ADV.1 | J9: ='Portage Bill'!V7 -> CASH ADV.2 | K9: ='Portage Bill'!W7 -> Slopchest | L9: ='Portage Bill'!X7 -> Telecon | M9: ='Portage Bill'!Y7 -> Other | N9: ='Portage Bill'!Z7 -> TOTAL DEDUCTIONS | O9: ='Portage Bill'!AA5 -> BALANCE | P9: ='Portage Bill'!AB5 -> PREVIOUS BALANCE | Q9: Union Contribution | R9: TOTAL | S9: SIGNATURE | U9: ='Portage Bill'!AC5 -> ****Leave pay for off-signers | V9: Preious Leave pay | W9: Accumulated Leave pay
C10: ='Portage Bill'!B8 -> 0 | D10: ='Portage Bill'!D8 -> Master | E10: ='Portage Bill'!Q8 -> 0 | F10: ='Portage Bill'!R8 -> 0 | G10: ='Portage Bill'!S8 -> 0 | H10: ='Portage Bill'!T8 -> 0 | I10: ='Portage Bill'!U8 -> 0 | J10: ='Portage Bill'!V8 -> 0 | K10: ='Portage Bill'!W8 -> 0 | L10: ='Portage Bill'!X8 -> 0 | ... N10: ='Portage Bill'!Z8 -> 0 | O10: =E10-N10 -> 0 | P10: ='Portage Bill'!AB8 -> 0 | R10: =SUM(O10:Q10) -> 0 | U10: 0 | V10: 0 | W10: =V10+F10-U10 -> 0
A11: ='Portage Bill'!#REF! -> #REF! | B11: ='Portage Bill'!B9 -> 0 | C11: ='Portage Bill'!B9 -> 0 | D11: ='Portage Bill'!D9 -> Chief officer | E11: ='Portage Bill'!Q9 -> 0 | F11: ='Portage Bill'!R9 -> 0 | G11: ='Portage Bill'!S9 -> 0 | H11: ='Portage Bill'!T9 -> 0 | I11: ='Portage Bill'!U9 -> 0 | J11: ='Portage Bill'!V9 -> 0 | K11: ='Portage Bill'!W9 -> 0 | L11: ='Portage Bill'!X9 -> 0 | ... N11: ='Portage Bill'!Z9 -> 0 | O11: =E11-N11 -> 0 | P11: ='Portage Bill'!AB9 -> 0 | R11: =SUM(O11:Q11) -> 0 | U11: 0 | V11: 0 | W11: =V11+F11-U11 -> 0
A12: ='Portage Bill'!#REF! -> #REF! | B12: ='Portage Bill'!B10 -> 0 | C12: ='Portage Bill'!B10 -> 0 | D12: ='Portage Bill'!D10 -> 2nd Officer | E12: ='Portage Bill'!Q10 -> 0 | F12: ='Portage Bill'!R10 -> 0 | G12: ='Portage Bill'!S10 -> 0 | H12: ='Portage Bill'!T10 -> 0 | I12: ='Portage Bill'!U10 -> 0 | J12: ='Portage Bill'!V10 -> 0 | K12: ='Portage Bill'!W10 -> 0 | L12: ='Portage Bill'!X10 -> 0 | ... N12: ='Portage Bill'!Z10 -> 0 | O12: =E12-N12 -> 0 | P12: ='Portage Bill'!AB10 -> 0 | R12: =SUM(O12:Q12) -> 0 | U12: 0 | V12: 0 | W12: =V12+F12-U12 -> 0
A13: ='Portage Bill'!#REF! -> #REF! | B13: ='Portage Bill'!B11 -> 0 | C13: ='Portage Bill'!B11 -> 0 | D13: ='Portage Bill'!D11 -> 3d Officer | E13: ='Portage Bill'!Q11 -> 0 | F13: ='Portage Bill'!R11 -> 0 | G13: ='Portage Bill'!S11 -> 0 | H13: ='Portage Bill'!T11 -> 0 | I13: ='Portage Bill'!U11 -> 0 | J13: ='Portage Bill'!V11 -> 0 | K13: ='Portage Bill'!W11 -> 0 | L13: ='Portage Bill'!X11 -> 0 | ... N13: ='Portage Bill'!Z11 -> 0 | O13: =E13-N13 -> 0 | P13: ='Portage Bill'!AB11 -> 0 | R13: =SUM(O13:Q13) -> 0 | U13: 0 | V13: 0 | W13: =V13+F13-U13 -> 0
A14: ='Portage Bill'!#REF! -> #REF! | B14: ='Portage Bill'!B12 -> 0 | C14: ='Portage Bill'!B12 -> 0 | D14: ='Portage Bill'!D12 -> Chief Engineer | E14: ='Portage Bill'!Q12 -> 0 | F14: ='Portage Bill'!R12 -> 0 | G14: ='Portage Bill'!S12 -> 0 | H14: ='Portage Bill'!T12 -> 0 | I14: ='Portage Bill'!U12 -> 0 | J14: ='Portage Bill'!V12 -> 0 | K14: ='Portage Bill'!W12 -> 0 | L14: ='Portage Bill'!X12 -> 0 | ... N14: ='Portage Bill'!Z12 -> 0 | O14: =E14-N14 -> 0 | P14: ='Portage Bill'!AB12 -> 0 | R14: =SUM(O14:Q14) -> 0 | U14: 0 | V14: 0 | W14: =V14+F14-U14 -> 0
A15: ='Portage Bill'!#REF! -> #REF! | B15: ='Portage Bill'!B13 -> 0 | C15: ='Portage Bill'!B13 -> 0 | D15: ='Portage Bill'!D13 -> 2nd Engineer | E15: ='Portage Bill'!Q13 -> 0 | F15: ='Portage Bill'!R13 -> 0 | G15: ='Portage Bill'!S13 -> 0 | H15: ='Portage Bill'!T13 -> 0 | I15: ='Portage Bill'!U13 -> 0 | J15: ='Portage Bill'!V13 -> 0 | K15: ='Portage Bill'!W13 -> 0 | L15: ='Portage Bill'!X13 -> 0 | ... N15: ='Portage Bill'!Z13 -> 0 | O15: =E15-N15 -> 0 | P15: ='Portage Bill'!AB13 -> 0 | R15: =SUM(O15:Q15) -> 0 | U15: 0 | V15: 0 | W15: =V15+F15-U15 -> 0
A16: ='Portage Bill'!#REF! -> #REF! | B16: ='Portage Bill'!B14 -> 0 | C16: ='Portage Bill'!B14 -> 0 | D16: ='Portage Bill'!D14 -> 3d Engineer | E16: ='Portage Bill'!Q14 -> 0 | F16: ='Portage Bill'!R14 -> 0 | G16: ='Portage Bill'!S14 -> 0 | H16: ='Portage Bill'!T14 -> 0 | I16: ='Portage Bill'!U14 -> 0 | J16: ='Portage Bill'!V14 -> 0 | K16: ='Portage Bill'!W14 -> 0 | L16: ='Portage Bill'!X14 -> 0 | ... N16: ='Portage Bill'!Z14 -> 0 | O16: =E16-N16 -> 0 | P16: ='Portage Bill'!AB14 -> 0 | R16: =SUM(O16:Q16) -> 0 | U16: 0 | V16: 0 | W16: =V16+F16-U16 -> 0
C17: ='Portage Bill'!B15 -> 0 | D17: ='Portage Bill'!D15 -> 4th Engineer | E17: ='Portage Bill'!Q15 -> 0 | F17: ='Portage Bill'!R15 -> 0 | G17: ='Portage Bill'!S15 -> 0 | H17: ='Portage Bill'!T15 -> 0 | I17: ='Portage Bill'!U15 -> 0 | J17: ='Portage Bill'!V15 -> 0 | K17: ='Portage Bill'!W15 -> 0 | L17: ='Portage Bill'!X15 -> 0 | ... N17: ='Portage Bill'!Z15 -> 0 | O17: =E17-N17 -> 0 | P17: ='Portage Bill'!AB15 -> 0 | R17: =SUM(O17:Q17) -> 0 | U17: 0 | V17: 0 | W17: =V17+F17-U17 -> 0
C18: ='Portage Bill'!B16 -> 0 | D18: ='Portage Bill'!D16 -> El.ENG | E18: ='Portage Bill'!Q16 -> 0 | F18: ='Portage Bill'!R16 -> 0 | G18: ='Portage Bill'!S16 -> 0 | H18: ='Portage Bill'!T16 -> 0 | I18: ='Portage Bill'!U16 -> 0 | J18: ='Portage Bill'!V16 -> 0 | K18: ='Portage Bill'!W16 -> 0 | L18: ='Portage Bill'!X16 -> 0 | ... N18: ='Portage Bill'!Z16 -> 0 | O18: =E18-N18 -> 0 | P18: ='Portage Bill'!AB16 -> 0 | R18: =SUM(O18:Q18) -> 0 | U18: 0 | V18: 0 | W18: =V18+F18-U18 -> 0
C19: ='Portage Bill'!B17 -> 0 | D19: ='Portage Bill'!D17 -> Bosun | E19: ='Portage Bill'!Q17 -> 0 | F19: ='Portage Bill'!R17 -> 0 | G19: ='Portage Bill'!S17 -> 0 | H19: ='Portage Bill'!T17 -> 0 | I19: ='Portage Bill'!U17 -> 0 | J19: ='Portage Bill'!V17 -> 0 | K19: ='Portage Bill'!W17 -> 0 | L19: ='Portage Bill'!X17 -> 0 | ... N19: ='Portage Bill'!Z17 -> 0 | O19: =E19-N19 -> 0 | P19: ='Portage Bill'!AB17 -> 0 | R19: =SUM(O19:Q19) -> 0 | U19: 0 | V19: 0 | W19: =V19+F19-U19 -> 0
C20: ='Portage Bill'!B18 -> 0 | D20: ='Portage Bill'!D18 -> ABS | E20: ='Portage Bill'!Q18 -> 0 | F20: ='Portage Bill'!R18 -> 0 | G20: ='Portage Bill'!S18 -> 0 | H20: ='Portage Bill'!T18 -> 0 | I20: ='Portage Bill'!U18 -> 0 | J20: ='Portage Bill'!V18 -> 0 | K20: ='Portage Bill'!W18 -> 0 | L20: ='Portage Bill'!X18 -> 0 | ... N20: ='Portage Bill'!Z18 -> 0 | O20: =E20-N20 -> 0 | P20: ='Portage Bill'!AB18 -> 0 | R20: =SUM(O20:Q20) -> 0 | U20: 0 | V20: 0 | W20: =V20+F20-U20 -> 0
C21: ='Portage Bill'!B19 -> 0 | D21: ='Portage Bill'!D19 -> ABS | E21: ='Portage Bill'!Q19 -> 0 | F21: ='Portage Bill'!R19 -> 0 | G21: ='Portage Bill'!S19 -> 0 | H21: ='Portage Bill'!T19 -> 0 | I21: ='Portage Bill'!U19 -> 0 | J21: ='Portage Bill'!V19 -> 0 | K21: ='Portage Bill'!W19 -> 0 | L21: ='Portage Bill'!X19 -> 0 | ... N21: ='Portage Bill'!Z19 -> 0 | O21: =E21-N21 -> 0 | P21: ='Portage Bill'!AB19 -> 0 | R21: =SUM(O21:Q21) -> 0 | U21: 0 | V21: 0 | W21: =V21+F21-U21 -> 0
C22: ='Portage Bill'!B20 -> 0 | D22: ='Portage Bill'!D20 -> ABS | E22: ='Portage Bill'!Q20 -> 0 | F22: ='Portage Bill'!R20 -> 0 | G22: ='Portage Bill'!S20 -> 0 | H22: ='Portage Bill'!T20 -> 0 | I22: ='Portage Bill'!U20 -> 0 | J22: ='Portage Bill'!V20 -> 0 | K22: ='Portage Bill'!W20 -> 0 | L22: ='Portage Bill'!X20 -> 0 | ... N22: ='Portage Bill'!Z20 -> 0 | O22: =E22-N22 -> 0 | P22: ='Portage Bill'!AB20 -> 0 | R22: =SUM(O22:Q22) -> 0 | U22: 0 | V22: 0 | W22: =V22+F22-U22 -> 0
C23: ='Portage Bill'!B21 -> 0 | D23: ='Portage Bill'!D21 -> OS | E23: ='Portage Bill'!Q21 -> 0 | F23: ='Portage Bill'!R21 -> 0 | G23: ='Portage Bill'!S21 -> 0 | H23: ='Portage Bill'!T21 -> 0 | I23: ='Portage Bill'!U21 -> 0 | J23: ='Portage Bill'!V21 -> 0 | K23: ='Portage Bill'!W21 -> 0 | L23: ='Portage Bill'!X21 -> 0 | ... N23: ='Portage Bill'!Z21 -> 0 | O23: =E23-N23 -> 0 | P23: ='Portage Bill'!AB21 -> 0 | R23: =SUM(O23:Q23) -> 0 | U23: 0 | V23: 0 | W23: =V23+F23-U23 -> 0
C24: ='Portage Bill'!B22 -> 0 | D24: ='Portage Bill'!D22 -> OS | E24: ='Portage Bill'!Q22 -> 0 | F24: ='Portage Bill'!R22 -> 0 | G24: ='Portage Bill'!S22 -> 0 | H24: ='Portage Bill'!T22 -> 0 | I24: ='Portage Bill'!U22 -> 0 | J24: ='Portage Bill'!V22 -> 0 | K24: ='Portage Bill'!W22 -> 0 | L24: ='Portage Bill'!X22 -> 0 | ... N24: ='Portage Bill'!Z22 -> 0 | O24: =E24-N24 -> 0 | P24: ='Portage Bill'!AB22 -> 0 | R24: =SUM(O24:Q24) -> 0 | U24: 0 | V24: 0 | W24: =V24+F24-U24 -> 0
C25: ='Portage Bill'!B23 -> 0 | D25: ='Portage Bill'!D23 -> Motorman | E25: ='Portage Bill'!Q23 -> 0 | F25: ='Portage Bill'!R23 -> 0 | G25: ='Portage Bill'!S23 -> 0 | H25: ='Portage Bill'!T23 -> 0 | I25: ='Portage Bill'!U23 -> 0 | J25: ='Portage Bill'!V23 -> 0 | K25: ='Portage Bill'!W23 -> 0 | L25: ='Portage Bill'!X23 -> 0 | ... N25: ='Portage Bill'!Z23 -> 0 | O25: =E25-N25 -> 0 | P25: ='Portage Bill'!AB23 -> 0 | R25: =SUM(O25:Q25) -> 0 | U25: 0 | V25: 0 | W25: =V25+F25-U25 -> 0
C26: ='Portage Bill'!B24 -> 0 | D26: ='Portage Bill'!D24 -> Motorman | E26: ='Portage Bill'!Q24 -> 0 | F26: ='Portage Bill'!R24 -> 0 | G26: ='Portage Bill'!S24 -> 0 | H26: ='Portage Bill'!T24 -> 0 | I26: ='Portage Bill'!U24 -> 0 | J26: ='Portage Bill'!V24 -> 0 | K26: ='Portage Bill'!W24 -> 0 | L26: ='Portage Bill'!X24 -> 0 | ... N26: ='Portage Bill'!Z24 -> 0 | O26: =E26-N26 -> 0 | P26: ='Portage Bill'!AB24 -> 0 | R26: =SUM(O26:Q26) -> 0 | U26: 0 | V26: 0 | W26: =V26+F26-U26 -> 0
C27: ='Portage Bill'!B25 -> 0 | D27: ='Portage Bill'!D25 -> Motorman | E27: ='Portage Bill'!Q25 -> 0 | F27: ='Portage Bill'!R25 -> 0 | G27: ='Portage Bill'!S25 -> 0 | H27: ='Portage Bill'!T25 -> 0 | I27: ='Portage Bill'!U25 -> 0 | J27: ='Portage Bill'!V25 -> 0 | K27: ='Portage Bill'!W25 -> 0 | L27: ='Portage Bill'!X25 -> 0 | ... N27: ='Portage Bill'!Z25 -> 0 | O27: =E27-N27 -> 0 | P27: ='Portage Bill'!AB25 -> 0 | R27: =SUM(O27:Q27) -> 0 | U27: 0 | V27: 0 | W27: =V27+F27-U27 -> 0
C28: ='Portage Bill'!B26 -> 0 | D28: ='Portage Bill'!D26 -> Wiper | E28: ='Portage Bill'!Q26 -> 0 | F28: ='Portage Bill'!R26 -> 0 | G28: ='Portage Bill'!S26 -> 0 | H28: ='Portage Bill'!T26 -> 0 | I28: ='Portage Bill'!U26 -> 0 | J28: ='Portage Bill'!V26 -> 0 | K28: ='Portage Bill'!W26 -> 0 | L28: ='Portage Bill'!X26 -> 0 | ... N28: ='Portage Bill'!Z26 -> 0 | O28: =E28-N28 -> 0 | P28: ='Portage Bill'!AB26 -> 0 | R28: =SUM(O28:Q28) -> 0 | U28: 0 | V28: 0 | W28: =V28+F28-U28 -> 0
... C34: ='Portage Bill'!B32 -> 0 | D34: ='Portage Bill'!D32 -> 0 | E34: ='Portage Bill'!Q32 -> 0 | F34: ='Portage Bill'!R32 -> 0 | G34: ='Portage Bill'!S32 -> 0 | H34: ='Portage Bill'!T32 -> 0 | I34: ='Portage Bill'!U32 -> 0 | J34: ='Portage Bill'!V32 -> 0 | K34: ='Portage Bill'!W32 -> 0 | L34: ='Portage Bill'!X32 -> 0 | ... N34: ='Portage Bill'!Z32 -> 0 | O34: =E34-N34 -> 0 | P34: ='Portage Bill'!AB32 -> 0 | R34: =SUM(O34:Q34) -> 0 | U34: 0 | V34: 0 | W34: =V34+F34-U34 -> 0
C35: ='Portage Bill'!B33 -> 0 | D35: ='Portage Bill'!D33 -> 0 | E35: ='Portage Bill'!Q33 -> 0 | F35: ='Portage Bill'!R33 -> 0 | G35: ='Portage Bill'!S33 -> 0 | H35: ='Portage Bill'!T33 -> 0 | I35: ='Portage Bill'!U33 -> 0 | J35: ='Portage Bill'!V33 -> 0 | K35: ='Portage Bill'!W33 -> 0 | L35: ='Portage Bill'!X33 -> 0 | ... N35: ='Portage Bill'!Z33 -> 0 | O35: =E35-N35 -> 0 | P35: ='Portage Bill'!AB33 -> 0 | R35: =SUM(O35:Q35) -> 0 | U35: ='Portage Bill'!AC33 -> 0 | V35: 0 | W35: =V35+F35-U35 -> 0
C36: TOTAL | E36: =SUM(E10:E35) -> 0 | F36: =SUM(F10:F35) -> 0 | G36: =SUM(G10:G35) -> 0 | H36: =SUM(H10:H35) -> 0 | I36: =SUM(I10:I35) -> 0 | J36: =SUM(J10:J35) -> 0 | K36: =SUM(K10:K35) -> 0 | L36: =SUM(L10:L35) -> 0 | ... P36: =SUM(P10:P35) -> 0 | R36: =SUM(R10:R35) -> 0 | U36: =SUM(U10:U35) -> 0 | V36: =SUM(V10:V35) -> 0 | W36: =SUM(W10:W35) -> 0
C38: *Attention! Please fill green box only!
P39: ='Portage Bill'!D49 -> Master / /

Sheet Master
I1: Revision Number | J1: : | K1: 01
I2: Page Number | J2: : | K2: 1 of 1
D3: WAGE ACCOUNT
A6: ='Portage Bill'!B3 -> Vessel: | B6: ='Portage Bill'!C3 -> 0 | H6: Currency : | J6: USD
H7: Monthly Basic Wages: | K7: ='Portage Bill'!F59 -> 0
A8: Seaman: | B8: ='Portage Bill'!B8 -> 0 | H8: Monthly Company Bonus: | K8: ='Portage Bill'!J59 -> 0
A9: Rank: | B9: ='Portage Bill'!D8 -> Master | H9: Period on board:
A10: Signed on: | G10: Month: | I10: Days:
A12: EARNINGS
A13: Wages from | C13: ='Portage Bill'!G2 -> 41365 | D13: till | E13: ='Portage Bill'!K2 -> 41394 | F13: = | G13: nil | H13: months | I13: ='Portage Bill'!F8 -> 0 | J13: days | K13: ='Portage Bill'!G8 -> 0
A14: Overtime Fixed | K14: ='Portage Bill'!I8 -> 0
A15: Leave Pay | K15: ='Portage Bill'!N8 -> 0
A16: Bonus | K16: ='Portage Bill'!O8 -> 0
A17: Various | C17: ='Portage Bill'!L5 -> Travelling | K17: ='Portage Bill'!L8 -> 0
A18: Various | C18: ='Portage Bill'!J6 -> FIDELITY | K18: ='Portage Bill'!J8 -> 0
A19: Various | C19: ='Portage Bill'!K5 -> ALLOWANCE | K19: ='Portage Bill'!K8 -> 0
A20: Various | C20: ='Portage Bill'!P6 -> Bonus & Extras | K20: ='Portage Bill'!P8 -> 0
H21: TOTAL EARNINGS | K21: =SUM(K12:K20) -> 0
A23: Previous balance | K23: ='Portage Bill'!AB8 -> 0
A25: Leave pay (for off-signers only) | K25: ='Portage Bill'!AC8 -> 0
G27: GRAND TOTAL EARNINGS | K27: =SUM(K21:K26) -> 0
A29: DEDUCTIONS
A30: ='Portage Bill'!X7 -> Telecon | C30: ='Portage Bill'!X8 -> 0
A31: Canteen: | C31: ='Portage Bill'!W8 -> 0
A32: Cash advances: | C32: ='Portage Bill'!U8 -> 0
A33: Cash advances: | C33: ='Portage Bill'!V8 -> 0
A34: Single Payment | C34: ='Portage Bill'!T8 -> 0
A35: Other | C35: ='Portage Bill'!Y8 -> 0
A36: ='Portage Bill'!R7 -> ***Leave pay | C36: ='Portage Bill'!R8 -> 0
A37: Various:
A38: ='deduct list'!W9 -> Accumulated Leave pay | E38: ='deduct list'!W10 -> 0
A39: TOTAL DEDUCTIONS | C39: =SUM(C30:C38) -> 0
H40: ALLOTMENT | K40: ='Portage Bill'!S8 -> 0
H42: Balance of wages | K42: ='Portage Bill'!AD8 -> 0
A43: Date of discharge: | F43: Port:
A44: Reason of discharge:
A45: Balance of wages to be paid by
A46: Balance to be withheld until Company's decision.
A47: ****Leave pay is payable at the end of the contract.
A48: Payment of the above sum settles all my claims against Ship and Owners.
...

Sheet Chief mate
I1: Revision Number | J1: : | K1: 01
I2: Page Number | J2: : | K2: 1 of 1
D3: WAGE ACCOUNT
A6: ='Portage Bill'!B3 -> Vessel: | B6: ='Portage Bill'!C3 -> 0 | H6: Currency : | J6: USD
H7: Monthly Basic Wages: | K7: ='Portage Bill'!F60 -> 0
A8: Seaman: | B8: ='Portage Bill'!B9 -> 0 | H8: Monthly Company Bonus: | K8: ='Portage Bill'!J60 -> 0
A9: Rank: | B9: ='Portage Bill'!D9 -> Chief officer | H9: Period on board:
A10: Signed on: | G10: Month: | I10: Days:
A12: EARNINGS
A13: Wages from | C13: ='Portage Bill'!G2 -> 41365 | D13: till | E13: ='Portage Bill'!K2 -> 41394 | F13: = | G13: nil | H13: months | I13: ='Portage Bill'!F9 -> 0 | J13: days | K13: ='Portage Bill'!G9 -> 0
A14: Overtime Fixed | K14: ='Portage Bill'!I9 -> 0
A15: Leave Pay | K15: ='Portage Bill'!N9 -> 0
A16: Bonus | K16: ='Portage Bill'!O9 -> 0
A17: Various | C17: ='Portage Bill'!L5 -> Travelling | K17: ='Portage Bill'!L9 -> 0
A18: Various | C18: ='Portage Bill'!J6 -> FIDELITY | K18: ='Portage Bill'!J9 -> 0
A19: Various | C19: ='Portage Bill'!K5 -> ALLOWANCE | K19: ='Portage Bill'!K9 -> 0
A20: Various | C20: ='Portage Bill'!P6 -> Bonus & Extras | K20: ='Portage Bill'!P9 -> 0
H21: TOTAL EARNINGS | K21: =SUM(K12:K20) -> 0
A23: Previous balance | K23: ='Portage Bill'!AB9 -> 0
A25: Leave pay (for off-signers only) | K25: ='Portage Bill'!AC9 -> 0
G27: GRAND TOTAL EARNINGS | K27: =SUM(K21:K26) -> 0
A29: DEDUCTIONS
A30: ='Portage Bill'!X7 -> Telecon | C30: ='Portage Bill'!X9 -> 0
A31: Canteen: | C31: ='Portage Bill'!W9 -> 0
A32: Cash advances: | C32: ='Portage Bill'!U9 -> 0
A33: Cash advances: | C33: ='Portage Bill'!V9 -> 0
A34: Single Payment | C34: ='Portage Bill'!T9 -> 0
A35: Other | C35: ='Portage Bill'!Y9 -> 0
A36: ='Portage Bill'!R7 -> ***Leave pay | C36: ='Portage Bill'!R9 -> 0
A37: Various:
A38: ='deduct list'!W9 -> Accumulated Leave pay | E38: ='deduct list'!W11 -> 0
A39: TOTAL DEDUCTIONS | C39: =SUM(C30:C38) -> 0
H40: ALLOTMENT | K40: ='Portage Bill'!S9 -> 0
H42: Balance of wages | K42: ='Portage Bill'!AD9 -> 0
A43: Date of discharge: | F43: Port:
A44: Reason of discharge:
A45: Balance of wages to be paid by
A46: Balance to be withheld until Company's decision.
A47: ****Leave pay is payable at the end of the contract.
A48: Payment of the above sum settles all my claims against Ship and Owners.
...

Sheet 2nd mate
I1: Revision Number | J1: : | K1: 01
I2: Page Number | J2: : | K2: 1 of 1
D3: WAGE ACCOUNT
A6: ='Portage Bill'!B3 -> Vessel: | B6: ='Portage Bill'!C3 -> 0 | H6: Currency : | J6: USD
H7: Monthly Basic Wages: | K7: ='Portage Bill'!F61 -> 0
A8: Seaman: | B8: ='Portage Bill'!B10 -> 0 | H8: Monthly Company Bonus: | K8: ='Portage Bill'!J61 -> 0
A9: Rank: | B9: ='Portage Bill'!D10 -> 2nd Officer | H9: Period on board:
A10: Signed on: | G10: Month: | I10: Days:
A12: EARNINGS
A13: Wages from | C13: ='Portage Bill'!G2 -> 41365 | D13: till | E13: ='Portage Bill'!K2 -> 41394 | F13: = | G13: nil | H13: months | I13: ='Portage Bill'!F10 -> 0 | J13: days | K13: ='Portage Bill'!G10 -> 0
A14: Overtime Fixed | K14: ='Portage Bill'!I10 -> 0
A15: Leave Pay | K15: ='Portage Bill'!N10 -> 0
A16: Bonus | K16: ='Portage Bill'!O10 -> 0
A17: Various | C17: ='Portage Bill'!L5 -> Travelling | K17: ='Portage Bill'!L10 -> 0
A18: Various | C18: ='Portage Bill'!J6 -> FIDELITY | K18: ='Portage Bill'!J10 -> 0
A19: Various | C19: ='Portage Bill'!K5 -> ALLOWANCE | K19: ='Portage Bill'!K10 -> 0
A20: Various | C20: ='Portage Bill'!P6 -> Bonus & Extras | K20: ='Portage Bill'!P10 -> 0
H21: TOTAL EARNINGS | K21: =SUM(K12:K20) -> 0
A23: Previous balance | K23: ='Portage Bill'!AB10 -> 0
A25: Leave pay (for off-signers only) | K25: ='Portage Bill'!AC10 -> 0
G27: GRAND TOTAL EARNINGS | K27: =SUM(K21:K26) -> 0
A29: DEDUCTIONS
A30: ='Portage Bill'!X7 -> Telecon | C30: ='Portage Bill'!X10 -> 0
A31: Canteen: | C31: ='Portage Bill'!W10 -> 0
A32: Cash advances: | C32: ='Portage Bill'!U10 -> 0
A33: Cash advances: | C33: ='Portage Bill'!V10 -> 0
A34: Single Payment | C34: ='Portage Bill'!T10 -> 0
A35: Other | C35: ='Portage Bill'!Y10 -> 0
A36: ='Portage Bill'!R7 -> ***Leave pay | C36: ='Portage Bill'!R10 -> 0
A37: Various:
A38: ='deduct list'!W9 -> Accumulated Leave pay | E38: ='deduct list'!W12 -> 0
A39: TOTAL DEDUCTIONS | C39: =SUM(C30:C38) -> 0
H40: ALLOTMENT | K40: ='Portage Bill'!S10 -> 0
H42: Balance of wages | K42: ='Portage Bill'!AD10 -> 0
A43: Date of discharge: | F43: Port:
A44: Reason of discharge:
A45: Balance of wages to be paid by
A46: Balance to be withheld until Company's decision.
A47: ****Leave pay is payable at the end of the contract.
A48: Payment of the above sum settles all my claims against Ship and Owners.
...

Sheet 3rd mate
I1: Revision Number | J1: : | K1: 01
I2: Page Number | J2: : | K2: 1 of 1
D3: WAGE ACCOUNT
A6: ='Portage Bill'!B3 -> Vessel: | B6: ='Portage Bill'!C3 -> 0 | H6: Currency : | J6: USD
H7: Monthly Basic Wages: | K7: ='Portage Bill'!F62 -> 0
A8: Seaman: | B8: ='Portage Bill'!B11 -> 0 | H8: Monthly Company Bonus: | K8: ='Portage Bill'!J62 -> 0
A9: Rank: | B9: ='Portage Bill'!D11 -> 3d Officer | H9: Period on board:
A10: Signed on: | G10: Month: | I10: Days:
A12: EARNINGS
A13: Wages from | C13: ='Portage Bill'!G2 -> 41365 | D13: till | E13: ='Portage Bill'!K2 -> 41394 | F13: = | G13: nil | H13: months | I13: ='Portage Bill'!F11 -> 0 | J13: days | K13: ='Portage Bill'!G11 -> 0
A14: Overtime Fixed | K14: ='Portage Bill'!I11 -> 0
A15: Leave Pay | K15: ='Portage Bill'!N11 -> 0
A16: Bonus | K16: ='Portage Bill'!O11 -> 0
A17: Various | C17: ='Portage Bill'!L5 -> Travelling | K17: ='Portage Bill'!L11 -> 0
A18: Various | C18: ='Portage Bill'!J6 -> FIDELITY | K18: ='Portage Bill'!J11 -> 0
A19: Various | C19: ='Portage Bill'!K5 -> ALLOWANCE | K19: ='Portage Bill'!K11 -> 0
A20: Various | C20: ='Portage Bill'!P6 -> Bonus & Extras | K20: ='Portage Bill'!P11 -> 0
H21: TOTAL EARNINGS | K21: =SUM(K12:K20) -> 0
A23: Previous balance | K23: ='Portage Bill'!AB11 -> 0
A25: Leave pay (for off-signers only) | K25: ='Portage Bill'!AC11 -> 0
G27: GRAND TOTAL EARNINGS | K27: =SUM(K21:K26) -> 0
A29: DEDUCTIONS
A30: ='Portage Bill'!X7 -> Telecon | C30: ='Portage Bill'!X11 -> 0
A31: Canteen: | C31: ='Portage Bill'!W11 -> 0
A32: Cash advances: | C32: ='Portage Bill'!U11 -> 0
A33: Cash advances: | C33: ='Portage Bill'!V11 -> 0
A34: Single Payment | C34: ='Portage Bill'!T11 -> 0
A35: Other | C35: ='Portage Bill'!Y11 -> 0
A36: ='Portage Bill'!R7 -> ***Leave pay | C36: ='Portage Bill'!R11 -> 0
A37: Various:
A38: ='deduct list'!W9 -> Accumulated Leave pay | E38: ='deduct list'!W13 -> 0
A39: TOTAL DEDUCTIONS | C39: =SUM(C30:C38) -> 0
H40: ALLOTMENT | K40: ='Portage Bill'!S11 -> 0
H42: Balance of wages | K42: ='Portage Bill'!AD11 -> 0
A43: Date of discharge: | F43: Port:
A44: Reason of discharge:
A45: Balance of wages to be paid by
A46: Balance to be withheld until Company's decision.
A47: ****Leave pay is payable at the end of the contract.
A48: Payment of the above sum settles all my claims against Ship and Owners.
...

Sheet Chief Engineer
I1: Revision Number | J1: : | K1: 01
I2: Page Number | J2: : | K2: 1 of 1
D3: WAGE ACCOUNT
A6: ='Portage Bill'!B3 -> Vessel: | B6: ='Portage Bill'!C3 -> 0 | H6: Currency : | J6: USD
H7: Monthly Basic Wages: | K7: ='Portage Bill'!F63 -> 0
A8: Seaman: | B8: ='Portage Bill'!B12 -> 0 | H8: Monthly Company Bonus: | K8: ='Portage Bill'!J63 -> 0
A9: Rank: | B9: ='Portage Bill'!D12 -> Chief Engineer | H9: Period on board:
A10: Signed on: | G10: Month: | I10: Days:
A12: EARNINGS
A13: Wages from | C13: ='Portage Bill'!G2 -> 41365 | D13: till | E13: ='Portage Bill'!K2 -> 41394 | F13: = | G13: nil | H13: months | I13: ='Portage Bill'!F12 -> 0 | J13: days | K13: ='Portage Bill'!G12 -> 0
A14: Overtime Fixed | K14: ='Portage Bill'!I12 -> 0
A15: Leave Pay | K15: ='Portage Bill'!N12 -> 0
A16: Bonus | K16: ='Portage Bill'!O12 -> 0
A17: Various | C17: ='Portage Bill'!L5 -> Travelling | K17: ='Portage Bill'!L12 -> 0
A18: Various | C18: ='Portage Bill'!J6 -> FIDELITY | K18: ='Portage Bill'!J12 -> 0
A19: Various | C19: ='Portage Bill'!K5 -> ALLOWANCE | K19: ='Portage Bill'!K12 -> 0
A20: Various | C20: ='Portage Bill'!P6 -> Bonus & Extras | K20: ='Portage Bill'!P12 -> 0
H21: TOTAL EARNINGS | K21: =SUM(K12:K20) -> 0
A23: Previous balance | K23: ='Portage Bill'!AB12 -> 0
A25: Leave pay (for off-signers only) | K25: ='Portage Bill'!AC12 -> 0
G27: GRAND TOTAL EARNINGS | K27: =SUM(K21:K26) -> 0
A29: DEDUCTIONS
A30: ='Portage Bill'!X7 -> Telecon | C30: ='Portage Bill'!X12 -> 0
A31: Canteen: | C31: ='Portage Bill'!W12 -> 0
A32: Cash advances: | C32: ='Portage Bill'!U12 -> 0
A33: Cash advances: | C33: ='Portage Bill'!V12 -> 0
A34: Single Payment | C34: ='Portage Bill'!T12 -> 0
A35: Other | C35: ='Portage Bill'!Y12 -> 0
A36: ='Portage Bill'!R7 -> ***Leave pay | C36: ='Portage Bill'!R12 -> 0
A37: Various:
A38: ='deduct list'!W9 -> Accumulated Leave pay | E38: ='deduct list'!W14 -> 0
A39: TOTAL DEDUCTIONS | C39: =SUM(C30:C38) -> 0
H40: ALLOTMENT | K40: ='Portage Bill'!S12 -> 0
H42: Balance of wages | K42: ='Portage Bill'!AD12 -> 0
A43: Date of discharge: | F43: Port:
A44: Reason of discharge:
A45: Balance of wages to be paid by
A46: Balance to be withheld until Company's decision.
A47: ****Leave pay is payable at the end of the contract.
A48: Payment of the above sum settles all my claims against Ship and Owners.
...

Sheet 2nd Engineer
I1: Revision Number | J1: : | K1: 01
I2: Page Number | J2: : | K2: 1 of 1
D3: WAGE ACCOUNT
A6: ='Portage Bill'!B3 -> Vessel: | B6: ='Portage Bill'!C3 -> 0 | H6: Currency : | J6: USD
H7: Monthly Basic Wages: | K7: ='Portage Bill'!F64 -> 0
A8: Seaman: | B8: ='Portage Bill'!B13 -> 0 | H8: Monthly Company Bonus: | K8: ='Portage Bill'!J64 -> 0
A9: Rank: | B9: ='Portage Bill'!D13 -> 2nd Engineer | H9: Period on board:
A10: Signed on: | G10: Month: | I10: Days:
A12: EARNINGS
A13: Wages from | C13: ='Portage Bill'!G2 -> 41365 | D13: till | E13: ='Portage Bill'!K2 -> 41394 | F13: = | G13: nil | H13: months | I13: ='Portage Bill'!F13 -> 0 | J13: days | K13: ='Portage Bill'!G13 -> 0
A14: Overtime Fixed | K14: ='Portage Bill'!I13 -> 0
A15: Leave Pay | K15: ='Portage Bill'!N13 -> 0
A16: Bonus | K16: ='Portage Bill'!O13 -> 0
A17: Various | C17: ='Portage Bill'!L5 -> Travelling | K17: ='Portage Bill'!L13 -> 0
A18: Various | C18: ='Portage Bill'!J6 -> FIDELITY | K18: ='Portage Bill'!J13 -> 0
A19: Various | C19: ='Portage Bill'!K5 -> ALLOWANCE | K19: ='Portage Bill'!K13 -> 0
A20: Various | C20: ='Portage Bill'!P6 -> Bonus & Extras | K20: ='Portage Bill'!P13 -> 0
H21: TOTAL EARNINGS | K21: =SUM(K12:K20) -> 0
A23: Previous balance | K23: ='Portage Bill'!AB13 -> 0
A25: Leave pay (for off-signers only) | K25: ='Portage Bill'!AC13 -> 0
G27: GRAND TOTAL EARNINGS | K27: =SUM(K21:K26) -> 0
A29: DEDUCTIONS
A30: ='Portage Bill'!X7 -> Telecon | C30: ='Portage Bill'!X13 -> 0
A31: Canteen: | C31: ='Portage Bill'!W13 -> 0
A32: Cash advances: | C32: ='Portage Bill'!U13 -> 0
A33: Cash advances: | C33: ='Portage Bill'!V13 -> 0
A34: Single Payment | C34: ='Portage Bill'!T13 -> 0
A35: Other | C35: ='Portage Bill'!Y13 -> 0
A36: ='Portage Bill'!R7 -> ***Leave pay | C36: ='Portage Bill'!R13 -> 0
A37: Various:
A38: ='deduct list'!W9 -> Accumulated Leave pay | E38: ='deduct list'!W15 -> 0
A39: TOTAL DEDUCTIONS | C39: =SUM(C30:C38) -> 0
H40: ALLOTMENT | K40: ='Portage Bill'!S13 -> 0
H42: Balance of wages | K42: ='Portage Bill'!AD13 -> 0
A43: Date of discharge: | F43: Port:
A44: Reason of discharge:
A45: Balance of wages to be paid by
A46: Balance to be withheld until Company's decision.
A47: ****Leave pay is payable at the end of the contract.
A48: Payment of the above sum settles all my claims against Ship and Owners.
...

Sheet 3rd Engineer
I1: Revision Number | J1: : | K1: 01
I2: Page Number | J2: : | K2: 1 of 1
D3: WAGE ACCOUNT
A6: ='Portage Bill'!B3 -> Vessel: | B6: ='Portage Bill'!C3 -> 0 | H6: Currency : | J6: USD
H7: Monthly Basic Wages: | K7: ='Portage Bill'!F65 -> 0
A8: Seaman: | B8: ='Portage Bill'!B14 -> 0 | H8: Monthly Company Bonus: | K8: ='Portage Bill'!J65 -> 0
A9: Rank: | B9: ='Portage Bill'!D14 -> 3d Engineer | H9: Period on board:
A10: Signed on: | G10: Month: | I10: Days:
A12: EARNINGS
A13: Wages from | C13: ='Portage Bill'!G2 -> 41365 | D13: till | E13: ='Portage Bill'!K2 -> 41394 | F13: = | G13: nil | H13: months | I13: ='Portage Bill'!F14 -> 0 | J13: days | K13: ='Portage Bill'!G14 -> 0
A14: Overtime Fixed | K14: ='Portage Bill'!I14 -> 0
A15: Leave Pay | K15: ='Portage Bill'!N14 -> 0
A16: Bonus | K16: ='Portage Bill'!O14 -> 0
A17: Various | C17: ='Portage Bill'!L5 -> Travelling | K17: ='Portage Bill'!L14 -> 0
A18: Various | C18: ='Portage Bill'!J6 -> FIDELITY | K18: ='Portage Bill'!J14 -> 0
A19: Various | C19: ='Portage Bill'!K5 -> ALLOWANCE | K19: ='Portage Bill'!K14 -> 0
A20: Various | C20: ='Portage Bill'!P6 -> Bonus & Extras | K20: ='Portage Bill'!P14 -> 0
H21: TOTAL EARNINGS | K21: =SUM(K12:K20) -> 0
A23: Previous balance | K23: ='Portage Bill'!AB14 -> 0
A25: Leave pay (for off-signers only) | K25: ='Portage Bill'!AC14 -> 0
G27: GRAND TOTAL EARNINGS | K27: =SUM(K21:K26) -> 0
A29: DEDUCTIONS
A30: ='Portage Bill'!X7 -> Telecon | C30: ='Portage Bill'!X14 -> 0
A31: Canteen: | C31: ='Portage Bill'!W14 -> 0
A32: Cash advances: | C32: ='Portage Bill'!U14 -> 0
A33: Cash advances: | C33: ='Portage Bill'!V14 -> 0
A34: Single Payment | C34: ='Portage Bill'!T14 -> 0
A35: Other | C35: ='Portage Bill'!Y14 -> 0
A36: ='Portage Bill'!R7 -> ***Leave pay | C36: ='Portage Bill'!R14 -> 0
A37: Various:
A38: ='deduct list'!W9 -> Accumulated Leave pay | E38: ='deduct list'!W16 -> 0
A39: TOTAL DEDUCTIONS | C39: =SUM(C30:C38) -> 0
H40: ALLOTMENT | K40: ='Portage Bill'!S14 -> 0
H42: Balance of wages | K42: ='Portage Bill'!AD14 -> 0
A43: Date of discharge: | F43: Port:
A44: Reason of discharge:
A45: Balance of wages to be paid by
A46: Balance to be withheld until Company's decision.
A47: ****Leave pay is payable at the end of the contract.
A48: Payment of the above sum settles all my claims against Ship and Owners.
...

Sheet 4th Eng
I1: Revision Number | J1: : | K1: 01
I2: Page Number | J2: : | K2: 1 of 1
D3: WAGE ACCOUNT
A6: ='Portage Bill'!B3 -> Vessel: | B6: ='Portage Bill'!C3 -> 0 | H6: Currency : | J6: USD
H7: Monthly Basic Wages: | K7: ='Portage Bill'!F66 -> 0
A8: Seaman: | B8: ='Portage Bill'!B15 -> 0 | H8: Monthly Company Bonus: | K8: ='Portage Bill'!J66 -> 0
A9: Rank: | B9: ='Portage Bill'!D15 -> 4th Engineer | H9: Period on board:
A10: Signed on: | G10: Month: | I10: Days:
A12: EARNINGS
A13: Wages from | C13: ='Portage Bill'!G2 -> 41365 | D13: till | E13: ='Portage Bill'!K2 -> 41394 | F13: = | G13: nil | H13: months | I13: ='Portage Bill'!F15 -> 0 | J13: days | K13: ='Portage Bill'!G15 -> 0
A14: Overtime Fixed | K14: ='Portage Bill'!I15 -> 0
A15: Leave Pay | K15: ='Portage Bill'!N15 -> 0
A16: Bonus | K16: ='Portage Bill'!O15 -> 0
A17: Various | C17: ='Portage Bill'!L5 -> Travelling | K17: ='Portage Bill'!L15 -> 0
A18: Various | C18: ='Portage Bill'!J6 -> FIDELITY | K18: ='Portage Bill'!J15 -> 0
A19: Various | C19: ='Portage Bill'!K5 -> ALLOWANCE | K19: ='Portage Bill'!K15 -> 0
A20: Various | C20: ='Portage Bill'!P6 -> Bonus & Extras | K20: ='Portage Bill'!P15 -> 0
H21: TOTAL EARNINGS | K21: =SUM(K12:K20) -> 0
A23: Previous balance | K23: ='Portage Bill'!AB15 -> 0
A25: Leave pay (for off-signers only) | K25: ='Portage Bill'!AC15 -> 0
G27: GRAND TOTAL EARNINGS | K27: =SUM(K21:K26) -> 0
A29: DEDUCTIONS
A30: ='Portage Bill'!X7 -> Telecon | C30: ='Portage Bill'!X15 -> 0
A31: Canteen: | C31: ='Portage Bill'!W15 -> 0
A32: Cash advances: | C32: ='Portage Bill'!U15 -> 0
A33: Cash advances: | C33: ='Portage Bill'!V15 -> 0
A34: Single Payment | C34: ='Portage Bill'!T15 -> 0
A35: Other | C35: ='Portage Bill'!Y15 -> 0
A36: ='Portage Bill'!R7 -> ***Leave pay | C36: ='Portage Bill'!R15 -> 0
A37: Various:
A38: ='deduct list'!W9 -> Accumulated Leave pay | E38: ='deduct list'!W17 -> 0
A39: TOTAL DEDUCTIONS | C39: =SUM(C30:C38) -> 0
H40: ALLOTMENT | K40: ='Portage Bill'!S15 -> 0
H42: Balance of wages | K42: ='Portage Bill'!AD15 -> 0
A43: Date of discharge: | F43: Port:
A44: Reason of discharge:
A45: Balance of wages to be paid by
A46: Balance to be withheld until Company's decision.
A47: ****Leave pay is payable at the end of the contract.
A48: Payment of the above sum settles all my claims against Ship and Owners.
...

Sheet El.eng
I1: Revision Number | J1: : | K1: 01
I2: Page Number | J2: : | K2: 1 of 1
D3: WAGE ACCOUNT
A6: ='Portage Bill'!B3 -> Vessel: | B6: ='Portage Bill'!C3 -> 0 | H6: Currency : | J6: USD
H7: Monthly Basic Wages: | K7: ='Portage Bill'!F67 -> 0
A8: Seaman: | B8: ='Portage Bill'!B16 -> 0 | H8: Monthly Company Bonus: | K8: ='Portage Bill'!J67 -> 0
A9: Rank: | B9: ='Portage Bill'!D16 -> El.ENG | H9: Period on board:
A10: Signed on: | G10: Month: | I10: Days:
A12: EARNINGS
A13: Wages from | C13: ='Portage Bill'!G2 -> 41365 | D13: till | E13: ='Portage Bill'!K2 -> 41394 | F13: = | G13: nil | H13: months | I13: ='Portage Bill'!F16 -> 0 | J13: days | K13: ='Portage Bill'!G16 -> 0
A14: Overtime Fixed | K14: ='Portage Bill'!I16 -> 0
A15: Leave Pay | K15: ='Portage Bill'!N16 -> 0
A16: Bonus | K16: ='Portage Bill'!O16 -> 0
A17: Various | C17: ='Portage Bill'!L5 -> Travelling | K17: ='Portage Bill'!L16 -> 0
A18: Various | C18: ='Portage Bill'!J6 -> FIDELITY | K18: ='Portage Bill'!J16 -> 0
A19: Various | C19: ='Portage Bill'!K5 -> ALLOWANCE | K19: ='Portage Bill'!K16 -> 0
A20: Various | C20: ='Portage Bill'!P6 -> Bonus & Extras | K20: ='Portage Bill'!P16 -> 0
H21: TOTAL EARNINGS | K21: =SUM(K12:K20) -> 0
A23: Previous balance | K23: ='Portage Bill'!AB16 -> 0
A25: Leave pay (for off-signers only) | K25: ='Portage Bill'!AC16 -> 0
G27: GRAND TOTAL EARNINGS | K27: =SUM(K21:K26) -> 0
A29: DEDUCTIONS
A30: ='Portage Bill'!X7 -> Telecon | C30: ='Portage Bill'!X16 -> 0
A31: Canteen: | C31: ='Portage Bill'!W16 -> 0
A32: Cash advances: | C32: ='Portage Bill'!U16 -> 0
A33: Cash advances: | C33: ='Portage Bill'!V16 -> 0
A34: Single Payment | C34: ='Portage Bill'!T16 -> 0
A35: Other | C35: ='Portage Bill'!Y16 -> 0
A36: ='Portage Bill'!R7 -> ***Leave pay | C36: ='Portage Bill'!R16 -> 0
A37: Various:
A38: ='deduct list'!W9 -> Accumulated Leave pay | E38: ='deduct list'!W18 -> 0
A39: TOTAL DEDUCTIONS | C39: =SUM(C30:C38) -> 0
H40: ALLOTMENT | K40: ='Portage Bill'!S16 -> 0
H42: Balance of wages | K42: ='Portage Bill'!AD16 -> 0
A43: Date of discharge: | F43: Port:
A44: Reason of discharge:
A45: Balance of wages to be paid by
A46: Balance to be withheld until Company's decision.
A47: ****Leave pay is payable at the end of the contract.
A48: Payment of the above sum settles all my claims against Ship and Owners.
...

Sheet BSN
I1: Revision Number | J1: : | K1: 01
I2: Page Number | J2: : | K2: 1 of 1
D3: WAGE ACCOUNT
A6: ='Portage Bill'!B3 -> Vessel: | B6: ='Portage Bill'!C3 -> 0 | H6: Currency : | J6: USD
H7: Monthly Basic Wages: | K7: ='Portage Bill'!F68 -> 0
A8: Seaman: | B8: ='Portage Bill'!B17 -> 0 | H8: Monthly Company Bonus: | K8: ='Portage Bill'!J68 -> 0
A9: Rank: | B9: ='Portage Bill'!D17 -> Bosun | H9: Period on board:
A10: Signed on: | G10: Month: | I10: Days:
A12: EARNINGS
A13: Wages from | C13: ='Portage Bill'!G2 -> 41365 | D13: till | E13: ='Portage Bill'!K2 -> 41394 | F13: = | G13: nil | H13: months | I13: ='Portage Bill'!F17 -> 0 | J13: days | K13: ='Portage Bill'!G17 -> 0
A14: Overtime Fixed | K14: ='Portage Bill'!I17 -> 0
A15: Leave Pay | K15: ='Portage Bill'!N17 -> 0
A16: Bonus | K16: ='Portage Bill'!O17 -> 0
A17: Various | C17: ='Portage Bill'!L5 -> Travelling | K17: ='Portage Bill'!L17 -> 0
A18: Various | C18: ='Portage Bill'!J6 -> FIDELITY | K18: ='Portage Bill'!J17 -> 0
A19: Various | C19: ='Portage Bill'!K5 -> ALLOWANCE | K19: ='Portage Bill'!K17 -> 0
A20: Various | C20: ='Portage Bill'!P6 -> Bonus & Extras | K20: ='Portage Bill'!P17 -> 0
H21: TOTAL EARNINGS | K21: =SUM(K12:K20) -> 0
A23: Previous balance | K23: ='Portage Bill'!AB17 -> 0
A25: Leave pay (for off-signers only) | K25: ='Portage Bill'!AC17 -> 0
G27: GRAND TOTAL EARNINGS | K27: =SUM(K21:K26) -> 0
A29: DEDUCTIONS
A30: ='Portage Bill'!X7 -> Telecon | C30: ='Portage Bill'!X17 -> 0
A31: Canteen: | C31: ='Portage Bill'!W17 -> 0
A32: Cash advances: | C32: ='Portage Bill'!U17 -> 0
A33: Cash advances: | C33: ='Portage Bill'!V17 -> 0
A34: Single Payment | C34: ='Portage Bill'!T17 -> 0
A35: Other | C35: ='Portage Bill'!Y17 -> 0
A36: ='Portage Bill'!R7 -> ***Leave pay | C36: ='Portage Bill'!R17 -> 0
A37: Various:
A38: ='deduct list'!W9 -> Accumulated Leave pay | E38: ='deduct list'!W19 -> 0
A39: TOTAL DEDUCTIONS | C39: =SUM(C30:C38) -> 0
H40: ALLOTMENT | K40: ='Portage Bill'!S17 -> 0
H42: Balance of wages | K42: ='Portage Bill'!AD17 -> 0
A43: Date of discharge: | F43: Port:
A44: Reason of discharge:
A45: Balance of wages to be paid by
A46: Balance to be withheld until Company's decision.
A47: ****Leave pay is payable at the end of the contract.
A48: Payment of the above sum settles all my claims against Ship and Owners.
...

Sheet ABS1
I1: Revision Number | J1: : | K1: 01
I2: Page Number | J2: : | K2: 1 of 1
D3: WAGE ACCOUNT
A6: ='Portage Bill'!B3 -> Vessel: | B6: ='Portage Bill'!C3 -> 0 | H6: Currency : | J6: USD
H7: Monthly Basic Wages: | K7: ='Portage Bill'!F69 -> 0
A8: Seaman: | B8: ='Portage Bill'!B18 -> 0 | H8: Monthly Company Bonus: | K8: ='Portage Bill'!J69 -> 0
A9: Rank: | B9: ='Portage Bill'!D18 -> ABS | H9: Period on board:
A10: Signed on: | G10: Month: | I10: Days:
A12: EARNINGS
A13: Wages from | C13: ='Portage Bill'!G2 -> 41365 | D13: till | E13: ='Portage Bill'!K2 -> 41394 | F13: = | G13: nil | H13: months | I13: ='Portage Bill'!F18 -> 0 | J13: days | K13: ='Portage Bill'!G18 -> 0
A14: Overtime Fixed | K14: ='Portage Bill'!I18 -> 0
A15: Leave Pay | K15: ='Portage Bill'!N18 -> 0
A16: Bonus | K16: ='Portage Bill'!O18 -> 0
A17: Various | C17: ='Portage Bill'!L5 -> Travelling | K17: ='Portage Bill'!L18 -> 0
A18: Various | C18: ='Portage Bill'!J6 -> FIDELITY | K18: ='Portage Bill'!J18 -> 0
A19: Various | C19: ='Portage Bill'!K5 -> ALLOWANCE | K19: ='Portage Bill'!K18 -> 0
A20: Various | C20: ='Portage Bill'!P6 -> Bonus & Extras | K20: ='Portage Bill'!P18 -> 0
H21: TOTAL EARNINGS | K21: =SUM(K12:K20) -> 0
A23: Previous balance | K23: ='Portage Bill'!AB18 -> 0
A25: Leave pay (for off-signers only) | K25: ='Portage Bill'!AC18 -> 0
G27: GRAND TOTAL EARNINGS | K27: =SUM(K21:K26) -> 0
A29: DEDUCTIONS
A30: ='Portage Bill'!X7 -> Telecon | C30: ='Portage Bill'!X18 -> 0
A31: Canteen: | C31: ='Portage Bill'!W18 -> 0
A32: Cash advances: | C32: ='Portage Bill'!U18 -> 0
A33: Cash advances: | C33: ='Portage Bill'!V18 -> 0
A34: Single Payment | C34: ='Portage Bill'!T18 -> 0
A35: Other | C35: ='Portage Bill'!Y18 -> 0
A36: ='Portage Bill'!R7 -> ***Leave pay | C36: ='Portage Bill'!R18 -> 0
A37: Various:
A38: ='deduct list'!W9 -> Accumulated Leave pay | E38: ='deduct list'!W20 -> 0
A39: TOTAL DEDUCTIONS | C39: =SUM(C30:C38) -> 0
H40: ALLOTMENT | K40: ='Portage Bill'!S18 -> 0
H42: Balance of wages | K42: ='Portage Bill'!AD18 -> 0
A43: Date of discharge: | F43: Port:
A44: Reason of discharge:
A45: Balance of wages to be paid by
A46: Balance to be withheld until Company's decision.
A47: ****Leave pay is payable at the end of the contract.
A48: Payment of the above sum settles all my claims against Ship and Owners.
...

Sheet ABS2
I1: Revision Number | J1: : | K1: 01
I2: Page Number | J2: : | K2: 1 of 1
D3: WAGE ACCOUNT
A6: ='Portage Bill'!B3 -> Vessel: | B6: ='Portage Bill'!C3 -> 0 | H6: Currency : | J6: USD
H7: Monthly Basic Wages: | K7: ='Portage Bill'!F70 -> 0
A8: Seaman: | B8: ='Portage Bill'!B19 -> 0 | H8: Monthly Company Bonus: | K8: ='Portage Bill'!J70 -> 0
A9: Rank: | B9: ='Portage Bill'!D19 -> ABS | H9: Period on board:
A10: Signed on: | G10: Month: | I10: Days:
A12: EARNINGS
A13: Wages from | C13: ='Portage Bill'!G2 -> 41365 | D13: till | E13: ='Portage Bill'!K2 -> 41394 | F13: = | G13: nil | H13: months | I13: ='Portage Bill'!F19 -> 0 | J13: days | K13: ='Portage Bill'!G19 -> 0
A14: Overtime Fixed | K14: ='Portage Bill'!I19 -> 0
A15: Leave Pay | K15: ='Portage Bill'!N19 -> 0
A16: Bonus | K16: ='Portage Bill'!O19 -> 0
A17: Various | C17: ='Portage Bill'!L5 -> Travelling | K17: ='Portage Bill'!L19 -> 0
A18: Various | C18: ='Portage Bill'!J6 -> FIDELITY | K18: ='Portage Bill'!J19 -> 0
A19: Various | C19: ='Portage Bill'!K5 -> ALLOWANCE | K19: ='Portage Bill'!K19 -> 0
A20: Various | C20: ='Portage Bill'!P6 -> Bonus & Extras | K20: ='Portage Bill'!P19 -> 0
H21: TOTAL EARNINGS | K21: =SUM(K12:K20) -> 0
A23: Previous balance | K23: ='Portage Bill'!AB19 -> 0
A25: Leave pay (for off-signers only) | K25: ='Portage Bill'!AC19 -> 0
G27: GRAND TOTAL EARNINGS | K27: =SUM(K21:K26) -> 0
A29: DEDUCTIONS
A30: ='Portage Bill'!X7 -> Telecon | C30: ='Portage Bill'!X19 -> 0
A31: Canteen: | C31: ='Portage Bill'!W19 -> 0
A32: Cash advances: | C32: ='Portage Bill'!U19 -> 0
A33: Cash advances: | C33: ='Portage Bill'!V19 -> 0
A34: Single Payment | C34: ='Portage Bill'!T19 -> 0
A35: Other | C35: ='Portage Bill'!Y19 -> 0
A36: ='Portage Bill'!R7 -> ***Leave pay | C36: ='Portage Bill'!R19 -> 0
A37: Various:
A38: ='deduct list'!W9 -> Accumulated Leave pay | E38: ='deduct list'!W21 -> 0
A39: TOTAL DEDUCTIONS | C39: =SUM(C30:C38) -> 0
H40: ALLOTMENT | K40: ='Portage Bill'!S19 -> 0
H42: Balance of wages | K42: ='Portage Bill'!AD19 -> 0
A43: Date of discharge: | F43: Port:
A44: Reason of discharge:
A45: Balance of wages to be paid by
A46: Balance to be withheld until Company's decision.
A47: ****Leave pay is payable at the end of the contract.
A48: Payment of the above sum settles all my claims against Ship and Owners.
...

Sheet ABS 3 
I1: Revision Number | J1: : | K1: 01
I2: Page Number | J2: : | K2: 1 of 1
D3: WAGE ACCOUNT
A6: ='Portage Bill'!B3 -> Vessel: | B6: ='Portage Bill'!C3 -> 0 | H6: Currency : | J6: USD
H7: Monthly Basic Wages: | K7: ='Portage Bill'!F71 -> 0
A8: Seaman: | B8: ='Portage Bill'!B20 -> 0 | H8: Monthly Company Bonus: | K8: ='Portage Bill'!J71 -> 0
A9: Rank: | B9: ='Portage Bill'!D20 -> ABS | H9: Period on board:
A10: Signed on: | G10: Month: | I10: Days:
A12: EARNINGS
A13: Wages from | C13: ='Portage Bill'!G2 -> 41365 | D13: till | E13: ='Portage Bill'!K2 -> 41394 | F13: = | G13: nil | H13: months | I13: ='Portage Bill'!F20 -> 0 | J13: days | K13: ='Portage Bill'!G20 -> 0
A14: Overtime Fixed | K14: ='Portage Bill'!I20 -> 0
A15: Leave Pay | K15: ='Portage Bill'!N20 -> 0
A16: Bonus | K16: ='Portage Bill'!O20 -> 0
A17: Various | C17: ='Portage Bill'!L5 -> Travelling | K17: ='Portage Bill'!L20 -> 0
A18: Various | C18: ='Portage Bill'!J6 -> FIDELITY | K18: ='Portage Bill'!J20 -> 0
A19: Various | C19: ='Portage Bill'!K5 -> ALLOWANCE | K19: ='Portage Bill'!K20 -> 0
A20: Various | C20: ='Portage Bill'!P6 -> Bonus & Extras | K20: ='Portage Bill'!P20 -> 0
H21: TOTAL EARNINGS | K21: =SUM(K12:K20) -> 0
A23: Previous balance | K23: ='Portage Bill'!AB20 -> 0
A25: Leave pay (for off-signers only) | K25: ='Portage Bill'!AC20 -> 0
G27: GRAND TOTAL EARNINGS | K27: =SUM(K21:K26) -> 0
A29: DEDUCTIONS
A30: ='Portage Bill'!X7 -> Telecon | C30: ='Portage Bill'!X20 -> 0
A31: Canteen: | C31: ='Portage Bill'!W20 -> 0
A32: Cash advances: | C32: ='Portage Bill'!U20 -> 0
A33: Cash advances: | C33: ='Portage Bill'!V20 -> 0
A34: Single Payment | C34: ='Portage Bill'!T20 -> 0
A35: Other | C35: ='Portage Bill'!Y20 -> 0
A36: ='Portage Bill'!R7 -> ***Leave pay | C36: ='Portage Bill'!R20 -> 0
A37: Various:
A38: ='deduct list'!W9 -> Accumulated Leave pay | E38: ='deduct list'!W22 -> 0
A39: TOTAL DEDUCTIONS | C39: =SUM(C30:C38) -> 0
H40: ALLOTMENT | K40: ='Portage Bill'!S20 -> 0
H42: Balance of wages | K42: ='Portage Bill'!AD20 -> 0
A43: Date of discharge: | F43: Port:
A44: Reason of discharge:
A45: Balance of wages to be paid by
A46: Balance to be withheld until Company's decision.
A47: ****Leave pay is payable at the end of the contract.
A48: Payment of the above sum settles all my claims against Ship and Owners.
...

Sheet OS1
I1: Revision Number | J1: : | K1: 01
I2: Page Number | J2: : | K2: 1 of 1
D3: WAGE ACCOUNT
A6: ='Portage Bill'!B3 -> Vessel: | B6: ='Portage Bill'!C3 -> 0 | H6: Currency : | J6: USD
H7: Monthly Basic Wages: | K7: ='Portage Bill'!F72 -> 0
A8: Seaman: | B8: ='Portage Bill'!B21 -> 0 | H8: Monthly Company Bonus: | K8: ='Portage Bill'!J72 -> 0
A9: Rank: | B9: ='Portage Bill'!D21 -> OS | H9: Period on board:
A10: Signed on: | G10: Month: | I10: Days:
A12: EARNINGS
A13: Wages from | C13: ='Portage Bill'!G2 -> 41365 | D13: till | E13: ='Portage Bill'!K2 -> 41394 | F13: = | G13: nil | H13: months | I13: ='Portage Bill'!F21 -> 0 | J13: days | K13: ='Portage Bill'!G21 -> 0
A14: Overtime Fixed | K14: ='Portage Bill'!I21 -> 0
A15: Leave Pay | K15: ='Portage Bill'!N21 -> 0
A16: Bonus | K16: ='Portage Bill'!O21 -> 0
A17: Various | C17: ='Portage Bill'!L5 -> Travelling | K17: ='Portage Bill'!L21 -> 0
A18: Various | C18: ='Portage Bill'!J6 -> FIDELITY | K18: ='Portage Bill'!J21 -> 0
A19: Various | C19: ='Portage Bill'!K5 -> ALLOWANCE | K19: ='Portage Bill'!K21 -> 0
A20: Various | C20: ='Portage Bill'!P6 -> Bonus & Extras | K20: ='Portage Bill'!P21 -> 0
H21: TOTAL EARNINGS | K21: =SUM(K12:K20) -> 0
A23: Previous balance | K23: ='Portage Bill'!AB21 -> 0
A25: Leave pay (for off-signers only) | K25: ='Portage Bill'!AC21 -> 0
G27: GRAND TOTAL EARNINGS | K27: =SUM(K21:K26) -> 0
A29: DEDUCTIONS
A30: ='Portage Bill'!X7 -> Telecon | C30: ='Portage Bill'!X21 -> 0
A31: Canteen: | C31: ='Portage Bill'!W21 -> 0
A32: Cash advances: | C32: ='Portage Bill'!U21 -> 0
A33: Cash advances: | C33: ='Portage Bill'!V21 -> 0
A34: Single Payment | C34: ='Portage Bill'!T21 -> 0
A35: Other | C35: ='Portage Bill'!Y21 -> 0
A36: ='Portage Bill'!R7 -> ***Leave pay | C36: ='Portage Bill'!R21 -> 0
A37: Various:
A38: ='deduct list'!W9 -> Accumulated Leave pay | E38: ='deduct list'!W23 -> 0
A39: TOTAL DEDUCTIONS | C39: =SUM(C30:C38) -> 0
H40: ALLOTMENT | K40: ='Portage Bill'!S21 -> 0
H42: Balance of wages | K42: ='Portage Bill'!AD21 -> 0
A43: Date of discharge: | F43: Port:
A44: Reason of discharge:
A45: Balance of wages to be paid by
A46: Balance to be withheld until Company's decision.
A47: ****Leave pay is payable at the end of the contract.
A48: Payment of the above sum settles all my claims against Ship and Owners.
...

Sheet OS2
I1: Revision Number | J1: : | K1: 01
I2: Page Number | J2: : | K2: 1 of 1
D3: WAGE ACCOUNT
A6: ='Portage Bill'!B3 -> Vessel: | B6: ='Portage Bill'!C3 -> 0 | H6: Currency : | J6: USD
H7: Monthly Basic Wages: | K7: ='Portage Bill'!F73 -> 0
A8: Seaman: | B8: ='Portage Bill'!B22 -> 0 | H8: Monthly Company Bonus: | K8: ='Portage Bill'!J73 -> 0
A9: Rank: | B9: ='Portage Bill'!D22 -> OS | H9: Period on board:
A10: Signed on: | G10: Month: | I10: Days:
A12: EARNINGS
A13: Wages from | C13: ='Portage Bill'!G2 -> 41365 | D13: till | E13: ='Portage Bill'!K2 -> 41394 | F13: = | G13: nil | H13: months | I13: ='Portage Bill'!F22 -> 0 | J13: days | K13: ='Portage Bill'!G22 -> 0
A14: Overtime Fixed | K14: ='Portage Bill'!I22 -> 0
A15: Leave Pay | K15: ='Portage Bill'!N22 -> 0
A16: Bonus | K16: ='Portage Bill'!O22 -> 0
A17: Various | C17: ='Portage Bill'!L5 -> Travelling | K17: ='Portage Bill'!L22 -> 0
A18: Various | C18: ='Portage Bill'!J6 -> FIDELITY | K18: ='Portage Bill'!J22 -> 0
A19: Various | C19: ='Portage Bill'!K5 -> ALLOWANCE | K19: ='Portage Bill'!K22 -> 0
A20: Various | C20: ='Portage Bill'!P6 -> Bonus & Extras | K20: ='Portage Bill'!P22 -> 0
H21: TOTAL EARNINGS | K21: =SUM(K12:K20) -> 0
A23: Previous balance | K23: ='Portage Bill'!AB22 -> 0
A25: Leave pay (for off-signers only) | K25: ='Portage Bill'!AC22 -> 0
G27: GRAND TOTAL EARNINGS | K27: =SUM(K21:K26) -> 0
A29: DEDUCTIONS
A30: ='Portage Bill'!X7 -> Telecon | C30: ='Portage Bill'!X22 -> 0
A31: Canteen: | C31: ='Portage Bill'!W22 -> 0
A32: Cash advances: | C32: ='Portage Bill'!U22 -> 0
A33: Cash advances: | C33: ='Portage Bill'!V22 -> 0
A34: Single Payment | C34: ='Portage Bill'!T22 -> 0
A35: Other | C35: ='Portage Bill'!Y22 -> 0
A36: ='Portage Bill'!R7 -> ***Leave pay | C36: ='Portage Bill'!R22 -> 0
A37: Various:
A38: ='deduct list'!W9 -> Accumulated Leave pay | E38: ='deduct list'!W24 -> 0
A39: TOTAL DEDUCTIONS | C39: =SUM(C30:C38) -> 0
H40: ALLOTMENT | K40: ='Portage Bill'!S22 -> 0
H42: Balance of wages | K42: ='Portage Bill'!AD22 -> 0
A43: Date of discharge: | F43: Port:
A44: Reason of discharge:
A45: Balance of wages to be paid by
A46: Balance to be withheld until Company's decision.
A47: ****Leave pay is payable at the end of the contract.
A48: Payment of the above sum settles all my claims against Ship and Owners.
...

Sheet OLR1
I1: Revision Number | J1: : | K1: 01
I2: Page Number | J2: : | K2: 1 of 1
D3: WAGE ACCOUNT
A6: ='Portage Bill'!B3 -> Vessel: | B6: ='Portage Bill'!C3 -> 0 | H6: Currency : | J6: USD
H7: Monthly Basic Wages: | K7: ='Portage Bill'!F74 -> 0
A8: Seaman: | B8: ='Portage Bill'!B23 -> 0 | H8: Monthly Company Bonus: | K8: ='Portage Bill'!J74 -> 0
A9: Rank: | B9: ='Portage Bill'!D23 -> Motorman | H9: Period on board:
A10: Signed on: | G10: Month: | I10: Days:
A12: EARNINGS
A13: Wages from | C13: ='Portage Bill'!G2 -> 41365 | D13: till | E13: ='Portage Bill'!K2 -> 41394 | F13: = | G13: nil | H13: months | I13: ='Portage Bill'!F23 -> 0 | J13: days | K13: ='Portage Bill'!G23 -> 0
A14: Overtime Fixed | K14: ='Portage Bill'!I23 -> 0
A15: Leave Pay | K15: ='Portage Bill'!N23 -> 0
A16: Bonus | K16: ='Portage Bill'!O23 -> 0
A17: Various | C17: ='Portage Bill'!L5 -> Travelling | K17: ='Portage Bill'!L23 -> 0
A18: Various | C18: ='Portage Bill'!J6 -> FIDELITY | K18: ='Portage Bill'!J23 -> 0
A19: Various | C19: ='Portage Bill'!K5 -> ALLOWANCE | K19: ='Portage Bill'!K23 -> 0
A20: Various | C20: ='Portage Bill'!P6 -> Bonus & Extras | K20: ='Portage Bill'!P23 -> 0
H21: TOTAL EARNINGS | K21: =SUM(K12:K20) -> 0
A23: Previous balance | K23: ='Portage Bill'!AB23 -> 0
A25: Leave pay (for off-signers only) | K25: ='Portage Bill'!AC23 -> 0
G27: GRAND TOTAL EARNINGS | K27: =SUM(K21:K26) -> 0
A29: DEDUCTIONS
A30: ='Portage Bill'!X7 -> Telecon | C30: ='Portage Bill'!X23 -> 0
A31: Canteen: | C31: ='Portage Bill'!W23 -> 0
A32: Cash advances: | C32: ='Portage Bill'!U23 -> 0
A33: Cash advances: | C33: ='Portage Bill'!V23 -> 0
